Workbook
Name COMPUTO_TEMPLATE_VERSION: "v3.0.0"

Sheet SC_A_FV25
A1: STIMA PRELIMINARE — ECO SHOPPER / 2WIN SRL | Via dei Falegnami 1/D, Castello d'Argile (BO) | Documento Progettista ↔ Installatore | S1: Aprile 2026
A2: SCENARIO A — Solo FV 25 kWp (caldaie gas invariate) | M2: Prezzi al cliente finale — IVA esclusa | Oneri professionali NON inclusi | S2: 54 pan. JKM460N 460Wp | Inv. ibrido 25kW DC-coupled | PVGIS 1.490 kWh/kWp | SC%≈60%
A3: Articolo / Descrizione | B3: Marca / Rif. | C3: Specifiche tecniche e note | D3: q.ta | E3: P.U. netto install. € | F3: Importo fornitura € | G3: sc.% | H3: Costo materiale € | I3: op. acc% | J3: op.acc € | K3: inst. % | L3: install € | M3: ric. % | N3: ricarico € | O3: TOT riga € | P3: impr % | Q3: impr. € | R3: PREZZO CLIENTE € | S3: Nota / Fonte / Affidabilità | T3: h | U3: 2p | V3: gg
A4: Coefficienti individuali per riga (non uniformi) — vedi colonne I, K, M, P | I4: ↓ riga | K4: ↓ riga | M4: ↓ riga | P4: ↓ riga
A5: FORNITURA PANNELLI FOTOVOLTAICI
A6: Pannelli FV JKM460N-48HL4M-BDV-Z3-EU — n.54 pz. | B6: JinkoSolar Tiger Neo | C6: 460 Wp STC, N-type TOPCon bifacciale dual glass, η=23,02%, bifacialità φ=80%, T.C.Pmax −0,29%/°C (migliore del Si p-type). Garanzia prodotto 15a / potenza lineare 30a (87,4% a 30a, deg. 0,40%/a). Configurazione: 54 pannelli × 460 Wp = 24.8 kWp. | D6: 54 | E6: 105 | F6: =D6*E6 | G6: 0 | H6: =F6*(1-G6) | I6: 0.02 | J6: =H6*I6 | K6: 0.2 | L6: =(H6+J6)*K6 | M6: 0.22 | N6: =(H6+J6+L6)*M6 | O6: =H6+J6+L6+N6 | P6: 0.1 | Q6: =O6*P6 | R6: =O6+Q6 | S6: 〰️ prezzo netto installatore stimato 0,228 €/Wp — mercato IT 2026 N-type bifacciale: 0,20÷0,25 €/Wp | T6: =L6/52 | U6: =T6/2 | V6: =U6/8
A7: INVERTER, MISURA E PROTEZIONI
A8: Inverter ibrido trifase DC-coupled 25 kW | B8: SMA / Fronius / Huawei (da definire in fase esecutiva) | C8: 400V 3+N+PE 50Hz, predisposizione storage DC-coupled nativa, ≥2 MPPT indipendenti, monitoraggio remoto integrato, efficienza max >98%, conforme CEI 0-21, gestione SmartGrid per priorità autoconsumo. | D8: 1 | E8: 3900 | F8: =D8*E8 | G8: 0 | H8: =F8*(1-G8) | I8: 0.02 | J8: =H8*I8 | K8: 0.07 | L8: =(H8+J8)*K8 | M8: 0.25 | N8: =(H8+J8+L8)*M8 | O8: =H8+J8+L8+N8 | P8: 0.1 | Q8: =O8*P8 | R8: =O8+Q8 | S8: 〰️ stima listino 2026 — da confrontare con offerta installatore: SMA STP-X 25: ~3.500-4.200 €; Fronius GEN24 25: ~4.000-5.000 € | T8: =L8/52 | U8: =T8/2 | V8: =U8/8
A9: Quadro AC protezioni FV + SPI interno | C9: MCCB AC lato rete, SPD Classe II AC, sezionatore con blocco-porta, contattore, morsettiere, armadio IP65. | D9: 1 | E9: 540 | F9: =D9*E9 | G9: 0 | H9: =F9*(1-G9) | I9: 0.07 | J9: =H9*I9 | K9: 0.28 | L9: =(H9+J9)*K9 | M9: 0.22 | N9: =(H9+J9+L9)*M9 | O9: =H9+J9+L9+N9 | P9: 0.1 | Q9: =O9*P9 | R9: =O9+Q9 | S9: 〰️ stima | T9: =L9/52 | U9: =T9/2 | V9: =U9/8
A10: Contatore bidirezionale produzione + scambio | C10: Misura produzione, energia immessa e prelevata — obbligatorio per pratiche GSE e SSP. | D10: 1 | E10: 260 | F10: =D10*E10 | G10: 0 | H10: =F10*(1-G10) | I10: 0.07 | J10: =H10*I10 | K10: 0.28 | L10: =(H10+J10)*K10 | M10: 0.22 | N10: =(H10+J10+L10)*M10 | O10: =H10+J10+L10+N10 | P10: 0.1 | Q10: =O10*P10 | R10: =O10+Q10 | S10: 〰️ stima — verificare requisiti specifici E-Distribuzione | T10: =L10/52 | U10: =T10/2 | V10: =U10/8
A11: STRUTTURE DI MONTAGGIO — TETTO PIANO
A12: Struttura ballast tetto piano, inclinazione 35° — n.54 pannelli | B12: Schletter / K2 / Aerocompact | C12: Profili alluminio anodizzato, supporti acciaio zincato, inclinazione 35°, zavorra blocchi cls prefabbricati (no foratura copertura). Certificata carichi vento zona padana (EN 1991-1-4) e neve Zona I. NOTA: accesso copertura con scala permanente (esistente) — materiali saliti con tiraggio manuale, NO ponteggio. Pitch inter-fila 4,0m → area occupata 243 m² su ~580 m² disponibili. | D12: 1 | E12: 1600 | F12: =D12*E12 | G12: 0 | H12: =F12*(1-G12) | I12: 0.04 | J12: =H12*I12 | K12: 0.22 | L12: =(H12+J12)*K12 | M12: 0.22 | N12: =(H12+J12+L12)*M12 | O12: =H12+J12+L12+N12 | P12: 0.1 | Q12: =O12*P12 | R12: =O12+Q12 | S12: 〰️ stima — include bulloneria e zavorra. Verifica strutturale copertura necessaria (carico aggiuntivo ~15 kg/m²) | T12: =L12/52 | U12: =T12/2 | V12: =U12/8
A13: CABLAGGIO DC / AC / MESSA A TERRA
A14: Cavi DC 4mm² 1.800V doppio isolamento UV-resist. | C14: Cavi unipolari +/− dalle stringhe all'inverter, connettori MC4, passaggi stagni copertura, protezione meccanica. | D14: 1 | E14: 620 | F14: =D14*E14 | G14: 0 | H14: =F14*(1-G14) | I14: 0.07 | J14: =H14*I14 | K14: 0.28 | L14: =(H14+J14)*K14 | M14: 0.22 | N14: =(H14+J14+L14)*M14 | O14: =H14+J14+L14+N14 | P14: 0.1 | Q14: =O14*P14 | R14: =O14+Q14 | S14: 〰️ stima | T14: =L14/52 | U14: =T14/2 | V14: =U14/8
A15: Protezioni lato DC: scatole stringa + fusibili + sezionatore | C15: Box stringa IP65 per ogni stringa, fusibili 15A per polo, sezionatore DC 4P, SPD Classe II DC. | D15: 1 | E15: 400 | F15: =D15*E15 | G15: 0 | H15: =F15*(1-G15) | I15: 0.07 | J15: =H15*I15 | K15: 0.28 | L15: =(H15+J15)*K15 | M15: 0.22 | N15: =(H15+J15+L15)*M15 | O15: =H15+J15+L15+N15 | P15: 0.1 | Q15: =O15*P15 | R15: =O15+Q15 | S15: 〰️ stima | T15: =L15/52 | U15: =T15/2 | V15: =U15/8
A16: Cavo AC trifase inverter → quadro AC | C16: FG7OR 5G10mm² (stima 30m copertura→QE), conduit staffato. | D16: 1 | E16: 340 | F16: =D16*E16 | G16: 0 | H16: =F16*(1-G16) | I16: 0.07 | J16: =H16*I16 | K16: 0.28 | L16: =(H16+J16)*K16 | M16: 0.22 | N16: =(H16+J16+L16)*M16 | O16: =H16+J16+L16+N16 | P16: 0.1 | Q16: =O16*P16 | R16: =O16+Q16 | S16: 〰️ stima | T16: =L16/52 | U16: =T16/2 | V16: =U16/8
A17: Messa a terra strutture FV + equipotenziale | C17: Anello equipotenziale strutture metalliche, picchetto dispersore dedicato. | D17: 1 | E17: 230 | F17: =D17*E17 | G17: 0 | H17: =F17*(1-G17) | I17: 0.07 | J17: =H17*I17 | K17: 0.28 | L17: =(H17+J17)*K17 | M17: 0.22 | N17: =(H17+J17+L17)*M17 | O17: =H17+J17+L17+N17 | P17: 0.1 | Q17: =O17*P17 | R17: =O17+Q17 | S17: 〰️ stima | T17: =L17/52 | U17: =T17/2 | V17: =U17/8
A18: Conduit, passaggi copertura stagni, staffaggi | C18: Conduit corrugato UV-resist. in copertura, passaggi parete/copertura stagni, fascette inox, supporti cavo su struttura. | D18: 1 | E18: 380 | F18: =D18*E18 | G18: 0 | H18: =F18*(1-G18) | I18: 0.07 | J18: =H18*I18 | K18: 0.28 | L18: =(H18+J18)*K18 | M18: 0.22 | N18: =(H18+J18+L18)*M18 | O18: =H18+J18+L18+N18 | P18: 0.1 | Q18: =O18*P18 | R18: =O18+Q18 | S18: 〰️ stima | T18: =L18/52 | U18: =T18/2 | V18: =U18/8
A19: PREDISPOSIZIONE STORAGE
A20: Predisposizione accumulo batterie DC-coupled | C20: Cavi DC dall'inverter ibrido al vano batteria (stima 5m), morsettiera dedicata etichettata, spazio riservato armadio inverter. BATTERIA NON INCLUSA: analisi economica ha escluso storage attivo (consumo notturno <5 kWh/g, PB >25a). Rivalutare se si aggiunge ricarica auto aziendale o turni serali. | D20: 1 | E20: 290 | F20: =D20*E20 | G20: 0 | H20: =F20*(1-G20) | I20: 0.07 | J20: =H20*I20 | K20: 0.28 | L20: =(H20+J20)*K20 | M20: 0.22 | N20: =(H20+J20+L20)*M20 | O20: =H20+J20+L20+N20 | P20: 0.1 | Q20: =O20*P20 | R20: =O20+Q20 | S20: ✅ investimento minimo per opzionalità futura | T20: =L20/52 | U20: =T20/2 | V20: =U20/8
A21: PRATICHE E CONNESSIONE RETE
A22: Pratiche GSE — comunicazione preventiva + fine lavori + SSP | C22: Portale GSE: comunicazione preventiva impianto, dichiarazione fine lavori, iscrizione SSP (Scambio Sul Posto) o verifica autoconsumo istantaneo, SCIA se richiesta dal Comune. | D22: 1 | E22: 650 | F22: =D22*E22 | G22: 0 | H22: =F22*(1-G22) | I22: 0 | J22: =H22*I22 | K22: 0 | L22: =(H22+J22)*K22 | M22: 0.12 | N22: =(H22+J22+L22)*M22 | O22: =H22+J22+L22+N22 | P22: 0 | Q22: =O22*P22 | R22: =O22+Q22 | S22: 〰️ stima coordinamento pratiche — oneri tecnici a parte | T22: 0 | U22: 0 | V22: 0
A23: Connessione E-Distribuzione — preventivo e iter allacciamento | B23: E-DISTRIBUZIONE S.p.A. | C23: Preventivo connessione BT trifase, adeguamento protezione interfaccia (SPI se > soglia), iter autorizzativo stimato 60-90 giorni. IMPORTO DA PREVENTIVO FORMALE — stimato a upper bound prudenziale. | D23: 1 | E23: 2500 | F23: =D23*E23 | G23: 0 | H23: =F23*(1-G23) | I23: 0 | J23: 0 | K23: 0 | L23: 0 | M23: 0 | N23: =H23*M23 | O23: =H23+N23 | P23: 0 | Q23: =O23*P23 | R23: =O23+Q23 | S23: ⚠️ AZIONE IMMEDIATA: richiedere preventivo E-Distribuzione — il tempo di connessione vincola la data di entrata in esercizio | T23: 0 | U23: 0 | V23: 0
A24: TRASPORTO
A25: Trasporto materiali FV (pannelli + inverter + struttura) | D25: 1 | E25: 297 | F25: =D25*E25 | G25: 0 | H25: =F25*(1-G25) | I25: 0 | J25: 0 | K25: 0 | L25: 0 | M25: 0.12 | N25: =H25*M25 | O25: =H25+N25 | P25: 0 | Q25: =O25*P25 | R25: =O25+Q25 | S25: 〰️ stima proporzionale | T25: 0 | U25: 0 | V25: 0
A26: SUBTOTALE LAVORI — IVA esclusa | R26: =SUM(R6:R25) | T26: =SUM(T6:T25) | U26: =SUM(U6:U25) | V26: =SUM(V6:V25)
A27: ⚠️ ONERI PROFESSIONALI NON INCLUSI nel subtotale — da fatturare separatamente: Progettazione esecutiva impianto termico (DM 37/2008, PN > 35 kW → tecnico abilitato obbligatorio) | Direzione lavori | Pratiche CURIT / aggiornamento libretto impianto | Collaudo e verifica prestazionale. Stima indicativa oneri professionali: 8÷10% del subtotale lavori.
A28: NOTA: UPGRADE CONTRATTO POTENZA — NON nel computo — La potenza contrattuale attuale è 23 kW; picco misurato gen.2026: 39,7 kW (supero già in atto). Con PDC+VRF: picco stimato 50-55 kW. Richiedere upgrade POD a Enel/E-Distribuzione: costo una tantum ~300-800 €; impatto annuo quota potenza: stima +1.000÷1.500 €/anno — da inserire nel computo economico ma NON nel preventivo lavori.
A29: LEGENDA AFFIDABILITÀ: ✅ Verde = dato da fonte certa (offerta formale, misura) 〰️ Bianco/grigio = stima da listini o letteratura — da confermare con preventivo formale ⚠️ Arancio = dato critico — verificare prima di procedere Colonne gialle (I, K, M, P) = coefficienti individuali per riga

Sheet SC_B_PDC
A1: STIMA PRELIMINARE — ECO SHOPPER / 2WIN SRL | Via dei Falegnami 1/D, Castello d'Argile (BO) | Documento Progettista ↔ Installatore | S1: Aprile 2026
A2: SCENARIO B — Solo PDC Idronica (FV non incluso) | M2: Prezzi al cliente finale — IVA esclusa | Oneri professionali NON inclusi | S2: 2× RHOSS THAITI 122 R32 | SCOP 4,53 BT | A+++ | Demoliz. totale C.T. | Acciaio nero saldato
A3: Articolo / Descrizione | B3: Marca / Rif. | C3: Specifiche tecniche e note | D3: q.ta | E3: P.U. netto install. € | F3: Importo fornitura € | G3: sc.% | H3: Costo materiale € | I3: op. acc% | J3: op.acc € | K3: inst. % | L3: install € | M3: ric. % | N3: ricarico € | O3: TOT riga € | P3: impr % | Q3: impr. € | R3: PREZZO CLIENTE € | S3: Nota / Fonte / Affidabilità | T3: h | U3: 2p | V3: gg
A4: Coefficienti individuali per riga (non uniformi) — vedi colonne I, K, M, P | I4: ↓ riga | K4: ↓ riga | M4: ↓ riga | P4: ↓ riga
A5: DEMOLIZIONE E SMALTIMENTO — CENTRALE TERMICA
A6: Smontaggio e rottamazione n.2 caldaie Baltur PERFECTA 35 RK | C6: Smontaggio meccanico, disconnessione idraulica e gas; rottamazione (nessun F-gas nelle caldaie). Ripristino raccordi, tappatura linea gas a monte del rubinetto in C.T. | D6: 1 | E6: 600 | F6: =D6*E6 | G6: 0 | H6: =F6*(1-G6) | I6: 0.05 | J6: =H6*I6 | K6: 0.55 | L6: =(H6+J6)*K6 | M6: 0.25 | N6: =(H6+J6+L6)*M6 | O6: =H6+J6+L6+N6 | P6: 0.1 | Q6: =O6*P6 | R6: =O6+Q6 | S6: 〰️ stima a corpo — nessun costo F-Gas (caldaie a combustione) | T6: =L6/52 | U6: =T6/2 | V6: =U6/8
A7: Smontaggio e rottamazione n.2 circolatori gemellari Wilo TOP-SD esistenti | B7: Wilo TOP-SD 32/7 + TOP-SD 50/10 | C7: Smontaggio n.2 unità gemellari (1 girante attiva + 1 stand-by per unità), come da rilievo fotografico. Motori trifase a gradini (non EC): incompatibili con il controllo inverter della PDC e ad alta inefficienza. Rottamazione RAEE. | D7: 1 | E7: 250 | F7: =D7*E7 | G7: 0 | H7: =F7*(1-G7) | I7: 0.05 | J7: =H7*I7 | K7: 0.55 | L7: =(H7+J7)*K7 | M7: 0.25 | N7: =(H7+J7+L7)*M7 | O7: =H7+J7+L7+N7 | P7: 0.1 | Q7: =O7*P7 | R7: =O7+Q7 | S7: ✅ identificati da foto: TOP-SD 32/7 + TOP-SD 50/10 gemellari | T7: =L7/52 | U7: =T7/2 | V7: =U7/8
A8: Smontaggio totale tubazioni, valvole, coibentazione esistente in C.T. | C8: Tubo ferro verniciato rosso esistente (diametri vari DN32÷DN50÷DN65 stimati), valvole a sfera e di ritegno, staffaggi, vaso espansione, coibentazione. Smaltimento come ferraglia + RAEE dove applicabile. ASSUNZIONE: impianto secondario nei locali (manifold radiante + tubazioni) ESCLUSO — nuovo e tenuto. | D8: 1 | E8: 800 | F8: =D8*E8 | G8: 0 | H8: =F8*(1-G8) | I8: 0.05 | J8: =H8*I8 | K8: 0.55 | L8: =(H8+J8)*K8 | M8: 0.25 | N8: =(H8+J8+L8)*M8 | O8: =H8+J8+L8+N8 | P8: 0.1 | Q8: =O8*P8 | R8: =O8+Q8 | S8: 〰️ stima a corpo demolizione C.T. completa | T8: =L8/52 | U8: =T8/2 | V8: =U8/8
A9: FORNITURA PDC — offerta Rhoss OF2026-4-10_113722 del 10/04/2026
A10: THAITI 122 P0 — ElectaMAXI-ECO | B10: RHOSS | C10: PDC reversibile monoblocco R32 DC inverter, modulo idraulico integrato con circolatore EC primario, Pdesignh 29 kW EN14825 / SCOP 4,53 BT 35°C / A+++ — Coppia M/S: Pdesignh_tot 44 kW — copertura carico eff. 28 kW@−5°C con margine. Include KSA antivibranti. | D10: 2 | E10: 8500 | F10: =D10*E10 | G10: 0 | H10: =F10*(1-G10) | I10: 0.02 | J10: =H10*I10 | K10: 0.04 | L10: =(H10+J10)*K10 | M10: 0.28 | N10: =(H10+J10+L10)*M10 | O10: =H10+J10+L10+N10 | P10: 0.1 | Q10: =O10*P10 | R10: =O10+Q10 | S10: ⚠️ prezzo interpolato (THAITI 118=7.590 €, THAITI 130=9.456 €) — richiedere conferma | T10: =L10/52 | U10: =T10/2 | V10: =U10/8
A11: PRIMO AVVIAMENTO — obbligatorio garanzia 24 mesi | B11: Tecnico autorizzato RHOSS | C11: Verifica parametri, taratura, registrazione garanzia. Garanzia decorre da data avviamento (max 30 mesi da consegna). | D11: 2 | E11: 231.6 | F11: =D11*E11 | G11: 0 | H11: =F11*(1-G11) | I11: 0 | J11: 0 | K11: 0 | L11: 0 | M11: 0.15 | N11: =H11*M11 | O11: =H11+N11 | P11: 0 | Q11: =O11*P11 | R11: =O11+Q11 | S11: ✅ da offerta formale Rhoss | T11: 0 | U11: 0 | V11: 0
A12: DISGIUNTORE IDRAULICO E ACCESSORI RHOSS
A13: KAI-110 — Serbatoio inerziale / disgiuntore idraulico | B13: RHOSS | C13: 110 litri — disgiuntore idraulico primario (PDC) / secondario (distribuzione). Necessario con 2 PDC inverter M/S + più zone radianti: evita on/off frequenti del compressore inverter. Classe energetica A. | D13: 1 | E13: 720 | F13: =D13*E13 | G13: 0 | H13: =F13*(1-G13) | I13: 0.05 | J13: =H13*I13 | K13: 0.15 | L13: =(H13+J13)*K13 | M13: 0.28 | N13: =(H13+J13+L13)*M13 | O13: =H13+J13+L13+N13 | P13: 0.1 | Q13: =O13*P13 | R13: =O13+Q13 | S13: 〰️ stima da listino Rhoss — SCELTA PROGETTUALE: necessario in questa configurazione | T13: =L13/52 | U13: =T13/2 | V13: =U13/8
A14: KRIT — Resistenza elettrica integrativa | B14: RHOSS | C14: Integrazione per punte di carico sotto −5°C (stima ≤ 4% energia annua, ~80 ore/anno). Potenza da definire in esecutivo (indicativa 6÷9 kW). | D14: 1 | E14: 600 | F14: =D14*E14 | G14: 0 | H14: =F14*(1-G14) | I14: 0.05 | J14: =H14*I14 | K14: 0.15 | L14: =(H14+J14)*K14 | M14: 0.28 | N14: =(H14+J14+L14)*M14 | O14: =H14+J14+L14+N14 | P14: 0.1 | Q14: =O14*P14 | R14: =O14+Q14 | S14: 〰️ stima | T14: =L14/52 | U14: =T14/2 | V14: =U14/8
A15: IMPIANTO IDRAULICO — RIFACIMENTO TOTALE CENTRALE TERMICA
A16: Tubazioni acciaio nero saldato EN 10255 — rifacimento totale C.T. | B16: Tubo nero EN 10255 ser. M | C16: Rifacimento completo rete idraulica in C.T.: tubo acciaio nero saldato EN 10255 serie M, diametri DN32÷DN50÷DN65 come da progetto esecutivo. Include: taglio, filettatura o saldatura, raccorderia, staffaggi a muro, collaudo idraulico a 6 bar. Stima: ~30 m lineari totali in C.T. | D16: 1 | E16: 2800 | F16: =D16*E16 | G16: 0 | H16: =F16*(1-G16) | I16: 0.08 | J16: =H16*I16 | K16: 0.42 | L16: =(H16+J16)*K16 | M16: 0.28 | N16: =(H16+J16+L16)*M16 | O16: =H16+J16+L16+N16 | P16: 0.1 | Q16: =O16*P16 | R16: =O16+Q16 | S16: 〰️ stima lump-sum — acciaio nero (coerente con esistente, vedi foto). Prezzo da confermare con rilievo metrico C.T. | T16: =L16/52 | U16: =T16/2 | V16: =U16/8
A17: Coibentazione tubazioni C.T. — nuova, totale | B17: Armaflex / K-Flex | C17: Guaina elastomerica a cellule chiuse, spessore ≥ 25mm per DN50+, ≥ 19mm per DN≤40, finitura con nastro adesivo. Copre tutte le tubazioni nuove in C.T. incluse raccorderie e valvole. | D17: 1 | E17: 900 | F17: =D17*E17 | G17: 0 | H17: =F17*(1-G17) | I17: 0.06 | J17: =H17*I17 | K17: 0.38 | L17: =(H17+J17)*K17 | M17: 0.25 | N17: =(H17+J17+L17)*M17 | O17: =H17+J17+L17+N17 | P17: 0.1 | Q17: =O17*P17 | R17: =O17+Q17 | S17: 〰️ stima — dimensionamento da rilievo | T17: =L17/52 | U17: =T17/2 | V17: =U17/8
A18: Circolatore EC principale — distribuzione secondaria DN50 | B18: Wilo Stratos MAXO / Grundfos MAGNA3 | C18: Circuito secondario PDC → KAI → distribuzione radiante: 1× circolatore EC a velocità variabile DN50, P.U. max 340 W, controllo integrato ΔP costante/variabile, Classe energetica A (risparmio ~85% vs TOP-SD 50/10 esistente a 880W). Sostituzione 1 gemellare TOP-SD 50/10 esistente. | D18: 1 | E18: 750 | F18: =D18*E18 | G18: 0 | H18: =F18*(1-G18) | I18: 0.05 | J18: =H18*I18 | K18: 0.18 | L18: =(H18+J18)*K18 | M18: 0.28 | N18: =(H18+J18+L18)*M18 | O18: =H18+J18+L18+N18 | P18: 0.1 | Q18: =O18*P18 | R18: =O18+Q18 | S18: 〰️ stima — Wilo Stratos MAXO 50/0,5-9: ~650-900 € netto installatore | T18: =L18/52 | U18: =T18/2 | V18: =U18/8
A19: Circolatore EC zona distribuzione DN32 | B19: Wilo Stratos PICO / Grundfos MAGNA3 | C19: 1× circolatore EC a velocità variabile DN32 per circuito di zona (sostituzione gemellare TOP-SD 32/7 esistente). P.U. max 75 W vs 200 W esistente. | D19: 1 | E19: 380 | F19: =D19*E19 | G19: 0 | H19: =F19*(1-G19) | I19: 0.05 | J19: =H19*I19 | K19: 0.18 | L19: =(H19+J19)*K19 | M19: 0.28 | N19: =(H19+J19+L19)*M19 | O19: =H19+J19+L19+N19 | P19: 0.1 | Q19: =O19*P19 | R19: =O19+Q19 | S19: 〰️ stima — da confermare funzione dopo rilievo; il circuito radiante secondario (manifold nei locali) è nuovo e tenuto | T19: =L19/52 | U19: =T19/2 | V19: =U19/8
A20: Valvolame di intercettazione e ritegno — nuovi per PDC e circuiti | C20: Per ogni PDC: rubinetto sferico DN40 andata/ritorno + ritegno + filtro Y bronzo; vaso espansione membrana 24L; VS tarata 3 bar; manometro; sfiati aria automatici; raccordi antivibranti (n.4 flessibili). Materiale stimato a corpo per C.T. rifatta. | D20: 1 | E20: 1200 | F20: =D20*E20 | G20: 0 | H20: =F20*(1-G20) | I20: 0.06 | J20: =H20*I20 | K20: 0.25 | L20: =(H20+J20)*K20 | M20: 0.28 | N20: =(H20+J20+L20)*M20 | O20: =H20+J20+L20+N20 | P20: 0.1 | Q20: =O20*P20 | R20: =O20+Q20 | S20: 〰️ stima a corpo — da quantificare con lay-out esecutivo | T20: =L20/52 | U20: =T20/2 | V20: =U20/8
A21: Bilanciamento idraulico circuiti radianti a pavimento | C21: Installazione valvole bilanciatrici autoregolanti sugli anelli (stima n.10÷14 anelli da rilievo planimetrico) e taratura con flussimetro. Risolve il problema di comfort dichiarato (sbilanciamento zona uffici). NOTA: i manifold e le tubazioni nei locali sono nuovi e tenuti — solo la taratura è necessaria. | D21: 1 | E21: 1800 | F21: =D21*E21 | G21: 0 | H21: =F21*(1-G21) | I21: 0.06 | J21: =H21*I21 | K21: 0.25 | L21: =(H21+J21)*K21 | M21: 0.28 | N21: =(H21+J21+L21)*M21 | O21: =H21+J21+L21+N21 | P21: 0.1 | Q21: =O21*P21 | R21: =O21+Q21 | S21: 〰️ stima — voce CRITICA per risolvere lo sbilanciamento segnalato dal cliente. N.anelli da confermare con rilievo. | T21: =L21/52 | U21: =T21/2 | V21: =U21/8
A22: IMPIANTO ELETTRICO — QUADRO E ALIMENTAZIONI PDC
A23: Quadro elettrico C.T. — nuovo, dedicato PDC | B23: Hager / Legrand | C23: Nuovo quadro dedicato in sostituzione del vecchio (foto): sezioni GENERALE (interruttore magnetotermico 4P+N 63A), PDC 1 (MCCB 4P 25A + diff. 300mA), PDC 2 (MCCB 4P 25A + diff. 300mA), CIRCOLATORI (MCB 4P 10A × 2), CONTROLLO/AUSILIARI (MCB 1P × 4), SPD Classe II, morsettiere, schemi elettrici. Armadio plastica IP65. | D23: 1 | E23: 1400 | F23: =D23*E23 | G23: 0 | H23: =F23*(1-G23) | I23: 0.05 | J23: =H23*I23 | K23: 0.28 | L23: =(H23+J23)*K23 | M23: 0.25 | N23: =(H23+J23+L23)*M23 | O23: =H23+J23+L23+N23 | P23: 0.1 | Q23: =O23*P23 | R23: =O23+Q23 | S23: 〰️ stima — il vecchio quadro (foto) ha sezioni CALDAIA e logica a relè: non riutilizzabile per PDC inverter con controllo M/S | T23: =L23/52 | U23: =T23/2 | V23: =U23/8
A24: Cavi alimentazione PDC trifase 400V | C24: N.2 linee FG7OR 4G10mm² dal QE C.T. alle unità esterne (stima 2×15m = 30m totali), conduit corrugato staffato, passaggi parete, fascette inox. | D24: 1 | E24: 680 | F24: =D24*E24 | G24: 0 | H24: =F24*(1-G24) | I24: 0.07 | J24: =H24*I24 | K24: 0.32 | L24: =(H24+J24)*K24 | M24: 0.25 | N24: =(H24+J24+L24)*M24 | O24: =H24+J24+L24+N24 | P24: 0.1 | Q24: =O24*P24 | R24: =O24+Q24 | S24: 〰️ stima — lunghezza definitiva da rilievo posizionamento PDC | T24: =L24/52 | U24: =T24/2 | V24: =U24/8
A25: Cavi segnale: bus M/S + sonda T aria esterna + conduit | C25: Cavo RS485 collegamento master/slave (≤15m), cavo sonda temperatura aria esterna, conduit segnali separato dai cavi forza, etichettatura. | D25: 1 | E25: 240 | F25: =D25*E25 | G25: 0 | H25: =F25*(1-G25) | I25: 0.07 | J25: =H25*I25 | K25: 0.32 | L25: =(H25+J25)*K25 | M25: 0.25 | N25: =(H25+J25+L25)*M25 | O25: =H25+J25+L25+N25 | P25: 0.1 | Q25: =O25*P25 | R25: =O25+Q25 | S25: 〰️ stima | T25: =L25/52 | U25: =T25/2 | V25: =U25/8
A26: Messa a terra strutture + equipotenziale unità esterne | C26: Conduttori PE, morsetti equipotenziali, verifica e adeguamento dispersore esistente. | D26: 1 | E26: 160 | F26: =D26*E26 | G26: 0 | H26: =F26*(1-G26) | I26: 0.07 | J26: =H26*I26 | K26: 0.32 | L26: =(H26+J26)*K26 | M26: 0.25 | N26: =(H26+J26+L26)*M26 | O26: =H26+J26+L26+N26 | P26: 0.1 | Q26: =O26*P26 | R26: =O26+Q26 | S26: 〰️ stima | T26: =L26/52 | U26: =T26/2 | V26: =U26/8
A27: CHIUSURA FORNITURA GAS
A28: Chiusura contratto gas + disattivazione impianto in C.T. | B28: Hera Comm / impiantista abilitato | C28: Richiesta formale chiusura PDR 07150100003052 (Hera Comm), intervento gestore per tappatura PDR lato strada, smontaggio raccorderia gas in C.T., tappatura valvola principale. La chiusura PDR elimina la quota fissa gas (636 €/anno). | D28: 1 | E28: 280 | F28: =D28*E28 | G28: 0 | H28: =F28*(1-G28) | I28: 0.06 | J28: =H28*I28 | K28: 0.25 | L28: =(H28+J28)*K28 | M28: 0.28 | N28: =(H28+J28+L28)*M28 | O28: =H28+J28+L28+N28 | P28: 0.1 | Q28: =O28*P28 | R28: =O28+Q28 | S28: 〰️ stima — la chiusura del contratto è spesso gratuita lato gestore; il costo qui è la prestazione dell'impiantista | T28: =L28/52 | U28: =T28/2 | V28: =U28/8
A29: TRASPORTO
A30: Trasporto materiali e macchine | B30: RHOSS + altri fornitori | C30: RHOSS: collettame P.C. (da offerta 2× THAITI 118: 466 €, interpolato per 122). Varie: tubazioni, quadri, circolatori. | D30: 1 | E30: 750 | F30: =D30*E30 | G30: 0 | H30: =F30*(1-G30) | I30: 0 | J30: 0 | K30: 0 | L30: 0 | M30: 0.12 | N30: =H30*M30 | O30: =H30+N30 | P30: 0 | Q30: =O30*P30 | R30: =O30+Q30 | S30: 〰️ stima composita | T30: 0 | U30: 0 | V30: 0
A31: SUBTOTALE LAVORI — IVA esclusa | R31: =SUM(R6:R30) | T31: =SUM(T6:T30) | U31: =SUM(U6:U30) | V31: =SUM(V6:V30)
A32: ⚠️ ONERI PROFESSIONALI NON INCLUSI nel subtotale — da fatturare separatamente: Progettazione esecutiva impianto termico (DM 37/2008, PN > 35 kW → tecnico abilitato obbligatorio) | Direzione lavori | Pratiche CURIT / aggiornamento libretto impianto | Collaudo e verifica prestazionale. Stima indicativa oneri professionali: 8÷10% del subtotale lavori.
A33: NOTA: UPGRADE CONTRATTO POTENZA — NON nel computo — La potenza contrattuale attuale è 23 kW; picco misurato gen.2026: 39,7 kW (supero già in atto). Con PDC+VRF: picco stimato 50-55 kW. Richiedere upgrade POD a Enel/E-Distribuzione: costo una tantum ~300-800 €; impatto annuo quota potenza: stima +1.000÷1.500 €/anno — da inserire nel computo economico ma NON nel preventivo lavori.
A34: LEGENDA AFFIDABILITÀ: ✅ Verde = dato da fonte certa (offerta formale, misura) 〰️ Bianco/grigio = stima da listini o letteratura — da confermare con preventivo formale ⚠️ Arancio = dato critico — verificare prima di procedere Colonne gialle (I, K, M, P) = coefficienti individuali per riga

Sheet SC_C_FULL
A1: STIMA PRELIMINARE — ECO SHOPPER / 2WIN SRL | Via dei Falegnami 1/D, Castello d'Argile (BO) | | S1: Aprile 2026
A2: SCENARIO C — FV 35 kWp + PDC Idronica [RACCOMANDATO con CT 3.0] | M2: Prezzi al cliente finale — IVA esclusa | Oneri professionali NON inclusi | S2: 76 pan. JKM460N | Inv. 35kW | 2× THAITI 122 | SC%≈58% | Gas eliminato | CT 3.0 su PDC
A3: Articolo / Descrizione | B3: Marca / Rif. | C3: Specifiche tecniche e note | D3: q.ta | E3: P.U. netto install. € | F3: Importo fornitura € | G3: sc.% | H3: Costo materiale € | I3: op. acc% | J3: op.acc € | K3: inst. % | L3: install € | M3: ric. % | N3: ricarico € | O3: TOT riga € | P3: impr % | Q3: impr. € | R3: PREZZO TOTALE € | S3: Nota / Fonte / Affidabilità | T3: h | U3: 2p | V3: gg
A4: Coefficienti individuali per riga (non uniformi) — vedi colonne I, K, M, P | I4: ↓ riga | K4: ↓ riga | M4: ↓ riga | P4: ↓ riga
A5: ━━━━━━ SEZIONE 1 - FOTOVOLTAICO — 35 kWp ━━━━━━
A6: FORNITURA PANNELLI FOTOVOLTAICI
A7: Pannelli FV JKM460N-48HL4M-BDV-Z3-EU — n.76 pz. | B7: JinkoSolar Tiger Neo | C7: 460 Wp STC, N-type TOPCon bifacciale dual glass, η=23,02%, bifacialità φ=80%, T.C.Pmax −0,29%/°C (migliore del Si p-type). Garanzia prodotto 15a / potenza lineare 30a (87,4% a 30a, deg. 0,40%/a). Configurazione: 76 pannelli × 460 Wp = 35.0 kWp. | D7: 76 | E7: 105 | F7: =D7*E7 | G7: 0 | H7: =F7*(1-G7) | I7: 0.02 | J7: =H7*I7 | K7: 0.2 | L7: =(H7+J7)*K7 | M7: 0.22 | N7: =(H7+J7+L7)*M7 | O7: =H7+J7+L7+N7 | P7: 0.1 | Q7: =O7*P7 | R7: =O7+Q7 | S7: 〰️ prezzo netto installatore stimato 0,228 €/Wp — mercato IT 2026 N-type bifacciale: 0,20÷0,25 €/Wp | T7: =L7/52 | U7: =T7/2 | V7: =U7/8
A8: INVERTER, MISURA E PROTEZIONI
A9: Inverter ibrido trifase DC-coupled 35 kW | B9: SMA / Fronius / Huawei (da definire in fase esecutiva) | C9: 400V 3+N+PE 50Hz, predisposizione storage DC-coupled nativa, ≥2 MPPT indipendenti, monitoraggio remoto integrato, efficienza max >98%, conforme CEI 0-21, gestione SmartGrid per priorità autoconsumo. | D9: 1 | E9: 5100 | F9: =D9*E9 | G9: 0 | H9: =F9*(1-G9) | I9: 0.02 | J9: =H9*I9 | K9: 0.07 | L9: =(H9+J9)*K9 | M9: 0.25 | N9: =(H9+J9+L9)*M9 | O9: =H9+J9+L9+N9 | P9: 0.1 | Q9: =O9*P9 | R9: =O9+Q9 | S9: 〰️ stima listino 2026 — da confrontare con offerta installatore: SMA STP-X 25: ~3.500-4.200 €; Fronius GEN24 25: ~4.000-5.000 € | T9: =L9/52 | U9: =T9/2 | V9: =U9/8
A10: Quadro AC protezioni FV + SPI interno | C10: MCCB AC lato rete, SPD Classe II AC, sezionatore con blocco-porta, contattore, morsettiere, armadio IP65. | D10: 1 | E10: 540 | F10: =D10*E10 | G10: 0 | H10: =F10*(1-G10) | I10: 0.07 | J10: =H10*I10 | K10: 0.28 | L10: =(H10+J10)*K10 | M10: 0.22 | N10: =(H10+J10+L10)*M10 | O10: =H10+J10+L10+N10 | P10: 0.1 | Q10: =O10*P10 | R10: =O10+Q10 | S10: 〰️ stima | T10: =L10/52 | U10: =T10/2 | V10: =U10/8
A11: Contatore bidirezionale produzione + scambio | C11: Misura produzione, energia immessa e prelevata — obbligatorio per pratiche GSE e SSP. | D11: 1 | E11: 260 | F11: =D11*E11 | G11: 0 | H11: =F11*(1-G11) | I11: 0.07 | J11: =H11*I11 | K11: 0.28 | L11: =(H11+J11)*K11 | M11: 0.22 | N11: =(H11+J11+L11)*M11 | O11: =H11+J11+L11+N11 | P11: 0.1 | Q11: =O11*P11 | R11: =O11+Q11 | S11: 〰️ stima — verificare requisiti specifici E-Distribuzione | T11: =L11/52 | U11: =T11/2 | V11: =U11/8
A12: STRUTTURE DI MONTAGGIO — TETTO PIANO
A13: Struttura ballast tetto piano, inclinazione 35° — n.76 pannelli | B13: Schletter / K2 / Aerocompact | C13: Profili alluminio anodizzato, supporti acciaio zincato, inclinazione 35°, zavorra blocchi cls prefabbricati (no foratura copertura). Certificata carichi vento zona padana (EN 1991-1-4) e neve Zona I. NOTA: accesso copertura con scala permanente (esistente) — materiali saliti con tiraggio manuale, NO ponteggio. Pitch inter-fila 4,0m → area occupata 342 m² su ~580 m² disponibili. | D13: 1 | E13: 2100 | F13: =D13*E13 | G13: 0 | H13: =F13*(1-G13) | I13: 0.04 | J13: =H13*I13 | K13: 0.22 | L13: =(H13+J13)*K13 | M13: 0.22 | N13: =(H13+J13+L13)*M13 | O13: =H13+J13+L13+N13 | P13: 0.1 | Q13: =O13*P13 | R13: =O13+Q13 | S13: 〰️ stima — include bulloneria e zavorra. Verifica strutturale copertura necessaria (carico aggiuntivo ~15 kg/m²) | T13: =L13/52 | U13: =T13/2 | V13: =U13/8
A14: CABLAGGIO DC / AC / MESSA A TERRA
A15: Cavi DC 4mm² 1.800V doppio isolamento UV-resist. | C15: Cavi unipolari +/− dalle stringhe all'inverter, connettori MC4, passaggi stagni copertura, protezione meccanica. | D15: 1 | E15: 830 | F15: =D15*E15 | G15: 0 | H15: =F15*(1-G15) | I15: 0.07 | J15: =H15*I15 | K15: 0.28 | L15: =(H15+J15)*K15 | M15: 0.22 | N15: =(H15+J15+L15)*M15 | O15: =H15+J15+L15+N15 | P15: 0.1 | Q15: =O15*P15 | R15: =O15+Q15 | S15: 〰️ stima | T15: =L15/52 | U15: =T15/2 | V15: =U15/8
A16: Protezioni lato DC: scatole stringa + fusibili + sezionatore | C16: Box stringa IP65 per ogni stringa, fusibili 15A per polo, sezionatore DC 4P, SPD Classe II DC. | D16: 1 | E16: 480 | F16: =D16*E16 | G16: 0 | H16: =F16*(1-G16) | I16: 0.07 | J16: =H16*I16 | K16: 0.28 | L16: =(H16+J16)*K16 | M16: 0.22 | N16: =(H16+J16+L16)*M16 | O16: =H16+J16+L16+N16 | P16: 0.1 | Q16: =O16*P16 | R16: =O16+Q16 | S16: 〰️ stima | T16: =L16/52 | U16: =T16/2 | V16: =U16/8
A17: Cavo AC trifase inverter → quadro AC | C17: FG7OR 5G10mm² (stima 30m copertura→QE), conduit staffato. | D17: 1 | E17: 400 | F17: =D17*E17 | G17: 0 | H17: =F17*(1-G17) | I17: 0.07 | J17: =H17*I17 | K17: 0.28 | L17: =(H17+J17)*K17 | M17: 0.22 | N17: =(H17+J17+L17)*M17 | O17: =H17+J17+L17+N17 | P17: 0.1 | Q17: =O17*P17 | R17: =O17+Q17 | S17: 〰️ stima | T17: =L17/52 | U17: =T17/2 | V17: =U17/8
A18: Messa a terra strutture FV + equipotenziale | C18: Anello equipotenziale strutture metalliche, picchetto dispersore dedicato. | D18: 1 | E18: 230 | F18: =D18*E18 | G18: 0 | H18: =F18*(1-G18) | I18: 0.07 | J18: =H18*I18 | K18: 0.28 | L18: =(H18+J18)*K18 | M18: 0.22 | N18: =(H18+J18+L18)*M18 | O18: =H18+J18+L18+N18 | P18: 0.1 | Q18: =O18*P18 | R18: =O18+Q18 | S18: 〰️ stima | T18: =L18/52 | U18: =T18/2 | V18: =U18/8
A19: Conduit, passaggi copertura stagni, staffaggi | C19: Conduit corrugato UV-resist. in copertura, passaggi parete/copertura stagni, fascette inox, supporti cavo su struttura. | D19: 1 | E19: 440 | F19: =D19*E19 | G19: 0 | H19: =F19*(1-G19) | I19: 0.07 | J19: =H19*I19 | K19: 0.28 | L19: =(H19+J19)*K19 | M19: 0.22 | N19: =(H19+J19+L19)*M19 | O19: =H19+J19+L19+N19 | P19: 0.1 | Q19: =O19*P19 | R19: =O19+Q19 | S19: 〰️ stima | T19: =L19/52 | U19: =T19/2 | V19: =U19/8
A20: PREDISPOSIZIONE ACCUMULO
A21: Predisposizione accumulo batterie DC-coupled | C21: Cavi DC dall'inverter ibrido al vano batteria (stima 5m), morsettiera dedicata etichettata, spazio riservato armadio inverter. BATTERIA NON INCLUSA | D21: 1 | E21: 290 | F21: =D21*E21 | G21: 0 | H21: =F21*(1-G21) | I21: 0.07 | J21: =H21*I21 | K21: 0.28 | L21: =(H21+J21)*K21 | M21: 0.22 | N21: =(H21+J21+L21)*M21 | O21: =H21+J21+L21+N21 | P21: 0.1 | Q21: =O21*P21 | R21: =O21+Q21 | S21: ✅ investimento minimo per opzionalità futura | T21: =L21/52 | U21: =T21/2 | V21: =U21/8
A22: TRASPORTO
A23: Trasporto materiali FV (pannelli + inverter + struttura) | D23: 1 | E23: 418 | F23: =D23*E23 | G23: 0 | H23: =F23*(1-G23) | I23: 0 | J23: 0 | K23: 0 | L23: 0 | M23: 0.12 | N23: =H23*M23 | O23: =H23+N23 | P23: 0 | Q23: =O23*P23 | R23: =O23+Q23 | S23: 〰️ stima proporzionale | T23: 0 | U23: 0 | V23: 0
A24: SUBTOTALE LAVORI — IVA esclusa | B24: =A5 | R24: =SUM(R7:R23) | T24: =SUM(T7:T23) | U24: =SUM(U7:U23) | V24: =SUM(V7:V23)
A25: ━━━━━━ SEZIONE 2 - PDC IDRONICA ━━━━━━
A26: DEMOLIZIONE E SMALTIMENTO — CENTRALE TERMICA
A27: Smontaggio e rottamazione n.2 caldaie Baltur PERFECTA 35 RK | C27: Smontaggio meccanico, disconnessione idraulica e gas; rottamazione (nessun F-gas nelle caldaie). Ripristino raccordi, tappatura linea gas a monte del rubinetto in C.T. | D27: 1 | E27: 600 | F27: =D27*E27 | G27: 0 | H27: =F27*(1-G27) | I27: 0.05 | J27: =H27*I27 | K27: 0.55 | L27: =(H27+J27)*K27 | M27: 0.25 | N27: =(H27+J27+L27)*M27 | O27: =H27+J27+L27+N27 | P27: 0.1 | Q27: =O27*P27 | R27: =O27+Q27 | S27: 〰️ stima a corpo — nessun costo F-Gas (caldaie a combustione) | T27: =L27/52 | U27: =T27/2 | V27: =U27/8
A28: Smontaggio e rottamazione n.2 circolatori gemellari Wilo TOP-SD esistenti | B28: Wilo TOP-SD 32/7 + TOP-SD 50/10 | C28: Smontaggio n.2 unità gemellari (1 girante attiva + 1 stand-by per unità), come da rilievo fotografico. Motori trifase a gradini (non EC): incompatibili con il controllo inverter della PDC e ad alta inefficienza. Rottamazione RAEE. | D28: 1 | E28: 250 | F28: =D28*E28 | G28: 0 | H28: =F28*(1-G28) | I28: 0.05 | J28: =H28*I28 | K28: 0.55 | L28: =(H28+J28)*K28 | M28: 0.25 | N28: =(H28+J28+L28)*M28 | O28: =H28+J28+L28+N28 | P28: 0.1 | Q28: =O28*P28 | R28: =O28+Q28 | S28: ✅ identificati da foto: TOP-SD 32/7 + TOP-SD 50/10 gemellari | T28: =L28/52 | U28: =T28/2 | V28: =U28/8
A29: Smontaggio totale tubazioni, valvole, coibentazione esistente in C.T. | C29: Tubo ferro verniciato rosso esistente (diametri vari DN32÷DN50÷DN65 stimati), valvole a sfera e di ritegno, staffaggi, vaso espansione, coibentazione. Smaltimento come ferraglia + RAEE dove applicabile. ASSUNZIONE: impianto secondario nei locali (manifold radiante + tubazioni) ESCLUSO — nuovo e tenuto. | D29: 1 | E29: 800 | F29: =D29*E29 | G29: 0 | H29: =F29*(1-G29) | I29: 0.05 | J29: =H29*I29 | K29: 0.55 | L29: =(H29+J29)*K29 | M29: 0.25 | N29: =(H29+J29+L29)*M29 | O29: =H29+J29+L29+N29 | P29: 0.1 | Q29: =O29*P29 | R29: =O29+Q29 | S29: 〰️ stima a corpo demolizione C.T. completa | T29: =L29/52 | U29: =T29/2 | V29: =U29/8
A30: FORNITURA PDC
A31: THAITI 122 P0 — ElectaMAXI-ECO | B31: RHOSS | C31: PDC reversibile monoblocco R32 DC inverter, modulo idraulico integrato con circolatore EC primario, Pdesignh 29 kW EN14825 / SCOP 4,53 BT 35°C / A+++ — Coppia M/S: Pdesignh_tot 44 kW — copertura carico eff. 28 kW@−5°C con margine. Include KSA antivibranti. | D31: 2 | E31: 8500 | F31: =D31*E31 | G31: 0 | H31: =F31*(1-G31) | I31: 0.02 | J31: =H31*I31 | K31: 0.04 | L31: =(H31+J31)*K31 | M31: 0.28 | N31: =(H31+J31+L31)*M31 | O31: =H31+J31+L31+N31 | P31: 0.1 | Q31: =O31*P31 | R31: =O31+Q31 | S31: ⚠️ prezzo interpolato (THAITI 118=7.590 €, THAITI 130=9.456 €) — richiedere conferma | T31: =L31/52 | U31: =T31/2 | V31: =U31/8
A32: PRIMO AVVIAMENTO — obbligatorio garanzia 24 mesi | B32: Tecnico autorizzato RHOSS | C32: Verifica parametri, taratura, registrazione garanzia. Garanzia decorre da data avviamento (max 30 mesi da consegna). | D32: 2 | E32: 231.6 | F32: =D32*E32 | G32: 0 | H32: =F32*(1-G32) | I32: 0 | J32: 0 | K32: 0 | L32: 0 | M32: 0.15 | N32: =H32*M32 | O32: =H32+N32 | P32: 0 | Q32: =O32*P32 | R32: =O32+Q32 | S32: ✅ da offerta formale Rhoss | T32: 0 | U32: 0 | V32: 0
A33: DISGIUNTORE IDRAULICO E ACCESSORI RHOSS
A34: KAI-110 — Serbatoio inerziale / disgiuntore idraulico | B34: RHOSS | C34: 110 litri — disgiuntore idraulico primario (PDC) / secondario (distribuzione). Necessario con 2 PDC inverter M/S + più zone radianti: evita on/off frequenti del compressore inverter. Classe energetica A. | D34: 1 | E34: 720 | F34: =D34*E34 | G34: 0 | H34: =F34*(1-G34) | I34: 0.05 | J34: =H34*I34 | K34: 0.15 | L34: =(H34+J34)*K34 | M34: 0.28 | N34: =(H34+J34+L34)*M34 | O34: =H34+J34+L34+N34 | P34: 0.1 | Q34: =O34*P34 | R34: =O34+Q34 | S34: 〰️ stima da listino Rhoss — SCELTA PROGETTUALE: necessario in questa configurazione | T34: =L34/52 | U34: =T34/2 | V34: =U34/8
A35: KRIT — Resistenza elettrica integrativa | B35: RHOSS | C35: Integrazione per punte di carico sotto −5°C (stima ≤ 4% energia annua, ~80 ore/anno). Potenza da definire in esecutivo (indicativa 6÷9 kW). | D35: 1 | E35: 600 | F35: =D35*E35 | G35: 0 | H35: =F35*(1-G35) | I35: 0.05 | J35: =H35*I35 | K35: 0.15 | L35: =(H35+J35)*K35 | M35: 0.28 | N35: =(H35+J35+L35)*M35 | O35: =H35+J35+L35+N35 | P35: 0.1 | Q35: =O35*P35 | R35: =O35+Q35 | S35: 〰️ stima | T35: =L35/52 | U35: =T35/2 | V35: =U35/8
A36: IMPIANTO IDRAULICO — RIFACIMENTO TOTALE CENTRALE TERMICA
A37: Tubazioni acciaio nero saldato EN 10255 — rifacimento totale C.T. | B37: Tubo nero EN 10255 ser. M | C37: Rifacimento completo rete idraulica in C.T.: tubo acciaio nero saldato EN 10255 serie M, diametri DN32÷DN50÷DN65 come da progetto esecutivo. Include: taglio, filettatura o saldatura, raccorderia, staffaggi a muro, collaudo idraulico a 6 bar. Stima: ~30 m lineari totali in C.T. | D37: 1 | E37: 2800 | F37: =D37*E37 | G37: 0 | H37: =F37*(1-G37) | I37: 0.08 | J37: =H37*I37 | K37: 0.42 | L37: =(H37+J37)*K37 | M37: 0.28 | N37: =(H37+J37+L37)*M37 | O37: =H37+J37+L37+N37 | P37: 0.1 | Q37: =O37*P37 | R37: =O37+Q37 | S37: 〰️ stima lump-sum — acciaio nero (coerente con esistente, vedi foto). Prezzo da confermare con rilievo metrico C.T. | T37: =L37/52 | U37: =T37/2 | V37: =U37/8
A38: Coibentazione tubazioni C.T. — nuova, totale | B38: Armaflex / K-Flex | C38: Guaina elastomerica a cellule chiuse, spessore ≥ 25mm per DN50+, ≥ 19mm per DN≤40, finitura con nastro adesivo. Copre tutte le tubazioni nuove in C.T. incluse raccorderie e valvole. | D38: 1 | E38: 900 | F38: =D38*E38 | G38: 0 | H38: =F38*(1-G38) | I38: 0.06 | J38: =H38*I38 | K38: 0.38 | L38: =(H38+J38)*K38 | M38: 0.25 | N38: =(H38+J38+L38)*M38 | O38: =H38+J38+L38+N38 | P38: 0.1 | Q38: =O38*P38 | R38: =O38+Q38 | S38: 〰️ stima — dimensionamento da rilievo | T38: =L38/52 | U38: =T38/2 | V38: =U38/8
A39: Circolatore EC principale — distribuzione secondaria DN50 | B39: Wilo Stratos MAXO / Grundfos MAGNA3 | C39: Circuito secondario PDC → KAI → distribuzione radiante: 1× circolatore EC a velocità variabile DN50, P.U. max 340 W, controllo integrato ΔP costante/variabile, Classe energetica A (risparmio ~85% vs TOP-SD 50/10 esistente a 880W). Sostituzione 1 gemellare TOP-SD 50/10 esistente. | D39: 1 | E39: 750 | F39: =D39*E39 | G39: 0 | H39: =F39*(1-G39) | I39: 0.05 | J39: =H39*I39 | K39: 0.18 | L39: =(H39+J39)*K39 | M39: 0.28 | N39: =(H39+J39+L39)*M39 | O39: =H39+J39+L39+N39 | P39: 0.1 | Q39: =O39*P39 | R39: =O39+Q39 | S39: 〰️ stima — Wilo Stratos MAXO 50/0,5-9: ~650-900 € netto installatore | T39: =L39/52 | U39: =T39/2 | V39: =U39/8
A40: Circolatore EC zona distribuzione DN32 | B40: Wilo Stratos PICO / Grundfos MAGNA3 | C40: 1× circolatore EC a velocità variabile DN32 per circuito di zona (sostituzione gemellare TOP-SD 32/7 esistente). P.U. max 75 W vs 200 W esistente. | D40: 1 | E40: 380 | F40: =D40*E40 | G40: 0 | H40: =F40*(1-G40) | I40: 0.05 | J40: =H40*I40 | K40: 0.18 | L40: =(H40+J40)*K40 | M40: 0.28 | N40: =(H40+J40+L40)*M40 | O40: =H40+J40+L40+N40 | P40: 0.1 | Q40: =O40*P40 | R40: =O40+Q40 | S40: 〰️ stima — da confermare funzione dopo rilievo; il circuito radiante secondario (manifold nei locali) è nuovo e tenuto | T40: =L40/52 | U40: =T40/2 | V40: =U40/8
...

Sheet RIEPILOGO
A1: RIEPILOGO — ECO SHOPPER / 2WIN SRL — Stima Preliminare Aprile 2026
A2: PREZZI AL CLIENTE FINALE — IVA esclusa | Oneri professionali NON inclusi (stima +8÷10%) | Documento di interfaccia Progettista ↔ Installatore
A4: Voce / Indicatore | B4: Scenario A FV 25 kWp | C4: Scenario B PDC sola | D4: Scenario C FV 35+PDC | E4: Note e assunzioni principali | F4: Benchmark mercato
A5: 1. INVESTIMENTO TOTALE (IVA esclusa, oneri professionali esclusi)
A6: SUBTOTALE LAVORI | B6: =SC_A_FV25!R26 | C6: =SC_B_PDC!R31 | D6: =SC_C_FULL!R52 | E6: Da fogli COMPUTO — formule dinamiche (si aggiornano modificando i fogli)
A7: + Oneri professionali (~9% stima) | B7: =SC_A_FV25!R26*0.09 | C7: =SC_B_PDC!R31*0.09 | D7: =SC_C_FULL!R52*0.09 | E7: ⚠️ STIMA INDICATIVA — fatturata separatamente dal progettista
A8: TOTALE INCLUSO ONERI PROFESSIONALI (indicativo) | B8: =SC_A_FV25!R26*1.09 | C8: =SC_B_PDC!R31*1.09 | D8: =SC_C_FULL!R52*1.09 | E8: Indicativo — oneri professionali non nel computo
A10: 2. BENCHMARK DI MERCATO — Italia 2025-2026 (prezzi al cliente finale, IVA esclusa)
A11: Indicatore €/unità | B11: Nostra stima | C11: Benchmark LOW | D11: Benchmark HIGH | E11: Interpretazione | F11: Fonte
A12: FV — €/kWp installato (Sc.A, 25 kWp) | B12: =SC_A_FV25!R26/25 | C12: 1100 | D12: 1650 | E12: La stima si posiziona nel range benchmark (basso-medio). Il gap rispetto al benchmark mid è attribuibile a prezzi panel netti installatore vs prezzi retail. Usare come floor per trattativa. | F12: RSE Rapporto FV 2024; ENEA; IRENA 2024
A13: FV — €/kWp installato (Sc.C, 35 kWp) | B13: =SC_C_FULL!R52/35 | C13: 1050 | D13: 1550 | E13: Economie di cantiere con PDC: mobilizzazione unica, quadro condiviso → stima più competitiva. | F13: RSE/IRENA 2024
A14: PDC aria-acqua installata — €/kW_th (Pdesignh 44 kW EN14825) | B14: =SC_B_PDC!R31/44 | C14: 750 | D14: 1400 | E14: Include demolizione totale C.T. + rifacimento idraulico completo: questo sposta verso il range alto. Benchmark low è per sostituzioni semplici (pdc su impianto OK). La nostra stima è appropriata per la complessità del caso. | F14: ENEA 2024; IEA Heat Pumps 2024; prezzi installatori IT
A16: 3. RISPARMIO ANNUO E INDICATORI ECONOMICI (IVA esclusa, prezzi netti SRL)
A17: Voce | B17: Sc.A FV 25kWp | C17: Sc.B PDC | D17: Sc.C Full | E17: Note | F17: Incertezza
A18: Gas eliminato (Hera: 3.685 Smc/a × 0,863 + quota fissa) | B18: 0 | C18: 3829 | D18: 3829 | E18: Da bollette reali Hera Comm 2025-26 | F18: ✅ bassa
A19: El. aggiuntiva PDC (SCOP_eff 3,97) | B19: 0 | C19: -2418 | D19: -2418 | E19: 8.337 kWh × 0,29 €/kWh netto SRL | F19: 〰️ media
A20: FV autoconsumato (c_el = 0,29 €/kWh) | B20: 6731 | C20: 0 | D20: 8318 | E20: Sc.A 23.211 kWh; Sc.C 28.683 kWh | F20: 〰️ alta (cooling non misurato)
A21: FV esportato (RID stimato 0,09 €/kWh) | B21: 1176 | C21: 0 | D21: 2112 | E21: 〰️ stima GSE — soggetto a revisioni | F21: 〰️ alta
A22: RISPARMIO NETTO ANNO 1 (€/anno) | B22: 7907 | C22: 1411 | D22: 12239
A23: Payback semplice (anni) | B23: 3,3 | C23: 23,5 | D23: 6,6 | E23: Con CT 3.0: Sc.B→~13a, Sc.C→~4,5a
A24: VAN 20 anni r=5% g=2% (€) | B24: 91600 | C24: -17500 | D24: 103600 | E24: F=14,88; valore orientativo
A25: VAN 20a CON CT 3.0 PDC (€) | B25: n.a. | C25: -2500 | D25: 118600 | E25: CT 3.0 stima ~15.000 € su 5 anni
A27: 4. CONTO TERMICO 3.0 — STIMA INCENTIVO PDC (Scenari B e C)
A28: Apparecchiatura | B28: 2× RHOSS ElectaMAXI-ECO THAITI 122 P0 — R32 — A+++ bassa T
A29: Ci (incentivo unitario) | B29: 0,06 €/kWh (zona E, A+++ bassa T)
A30: Pdesignh totale | B30: 44 kW EN 14825
A31: Quf stimato | B31: 1.700 h/anno equivalenti (stima)
A32: kp fattore efficienza GSE | B32: 1,27 (stima zona E, A+++)
A33: Ei stimato | B33: 44 × 1.700 × 1,27 = 94.996 kWh/anno
A34: Cap 55% investimento PDC amm. | B34: 35.000 × 0,55 = 19.250 €
A35: INCENTIVO ADOTTATO (min tra le due) | B35: ~15.000 € STIMA ±30% — calcolo formale GSE obbligatorio
A36: Rate annue (5 anni) | B36: ~3.000 €/anno
